Workbook

Sheet Resumen
A1: Resumen de ejecución — Tu Evento
A2: Los totales se calculan solos desde la hoja «Casos de prueba». Solo edita las columnas Resultado obtenido, Estado, Fecha, Responsable y Observaciones. El estado se elige de la lista.
A4: Módulo | B4: Total | C4: Aprobados | D4: Fallidos | E4: Bloqueados | F4: Pendientes | G4: % Aprobado
A5: Autenticación | B5: =COUNTIF('Casos de prueba'!$B:$B,A5) -> 32 | C5: =COUNTIFS('Casos de prueba'!$B:$B,$A5,'Casos de prueba'!$L:$L,"Aprobado") -> 0 | D5: =COUNTIFS('Casos de prueba'!$B:$B,$A5,'Casos de prueba'!$L:$L,"Fallido") -> 0 | E5: =COUNTIFS('Casos de prueba'!$B:$B,$A5,'Casos de prueba'!$L:$L,"Bloqueado") -> 0 | F5: =COUNTIFS('Casos de prueba'!$B:$B,$A5,'Casos de prueba'!$L:$L,"Pendiente") -> 32 | G5: =IF(B5=0,0,C5/B5) -> 0
A6: Usuarios | B6: =COUNTIF('Casos de prueba'!$B:$B,A6) -> 9 | C6: =COUNTIFS('Casos de prueba'!$B:$B,$A6,'Casos de prueba'!$L:$L,"Aprobado") -> 0 | D6: =COUNTIFS('Casos de prueba'!$B:$B,$A6,'Casos de prueba'!$L:$L,"Fallido") -> 0 | E6: =COUNTIFS('Casos de prueba'!$B:$B,$A6,'Casos de prueba'!$L:$L,"Bloqueado") -> 0 | F6: =COUNTIFS('Casos de prueba'!$B:$B,$A6,'Casos de prueba'!$L:$L,"Pendiente") -> 9 | G6: =IF(B6=0,0,C6/B6) -> 0
A7: Administración | B7: =COUNTIF('Casos de prueba'!$B:$B,A7) -> 6 | C7: =COUNTIFS('Casos de prueba'!$B:$B,$A7,'Casos de prueba'!$L:$L,"Aprobado") -> 0 | D7: =COUNTIFS('Casos de prueba'!$B:$B,$A7,'Casos de prueba'!$L:$L,"Fallido") -> 0 | E7: =COUNTIFS('Casos de prueba'!$B:$B,$A7,'Casos de prueba'!$L:$L,"Bloqueado") -> 0 | F7: =COUNTIFS('Casos de prueba'!$B:$B,$A7,'Casos de prueba'!$L:$L,"Pendiente") -> 6 | G7: =IF(B7=0,0,C7/B7) -> 0
A8: Perfil | B8: =COUNTIF('Casos de prueba'!$B:$B,A8) -> 5 | C8: =COUNTIFS('Casos de prueba'!$B:$B,$A8,'Casos de prueba'!$L:$L,"Aprobado") -> 0 | D8: =COUNTIFS('Casos de prueba'!$B:$B,$A8,'Casos de prueba'!$L:$L,"Fallido") -> 0 | E8: =COUNTIFS('Casos de prueba'!$B:$B,$A8,'Casos de prueba'!$L:$L,"Bloqueado") -> 0 | F8: =COUNTIFS('Casos de prueba'!$B:$B,$A8,'Casos de prueba'!$L:$L,"Pendiente") -> 5 | G8: =IF(B8=0,0,C8/B8) -> 0
A9: Eventos | B9: =COUNTIF('Casos de prueba'!$B:$B,A9) -> 21 | C9: =COUNTIFS('Casos de prueba'!$B:$B,$A9,'Casos de prueba'!$L:$L,"Aprobado") -> 0 | D9: =COUNTIFS('Casos de prueba'!$B:$B,$A9,'Casos de prueba'!$L:$L,"Fallido") -> 0 | E9: =COUNTIFS('Casos de prueba'!$B:$B,$A9,'Casos de prueba'!$L:$L,"Bloqueado") -> 0 | F9: =COUNTIFS('Casos de prueba'!$B:$B,$A9,'Casos de prueba'!$L:$L,"Pendiente") -> 21 | G9: =IF(B9=0,0,C9/B9) -> 0
A10: Media y layout | B10: =COUNTIF('Casos de prueba'!$B:$B,A10) -> 7 | C10: =COUNTIFS('Casos de prueba'!$B:$B,$A10,'Casos de prueba'!$L:$L,"Aprobado") -> 0 | D10: =COUNTIFS('Casos de prueba'!$B:$B,$A10,'Casos de prueba'!$L:$L,"Fallido") -> 0 | E10: =COUNTIFS('Casos de prueba'!$B:$B,$A10,'Casos de prueba'!$L:$L,"Bloqueado") -> 0 | F10: =COUNTIFS('Casos de prueba'!$B:$B,$A10,'Casos de prueba'!$L:$L,"Pendiente") -> 7 | G10: =IF(B10=0,0,C10/B10) -> 0
A11: Ratings y comentarios | B11: =COUNTIF('Casos de prueba'!$B:$B,A11) -> 6 | C11: =COUNTIFS('Casos de prueba'!$B:$B,$A11,'Casos de prueba'!$L:$L,"Aprobado") -> 0 | D11: =COUNTIFS('Casos de prueba'!$B:$B,$A11,'Casos de prueba'!$L:$L,"Fallido") -> 0 | E11: =COUNTIFS('Casos de prueba'!$B:$B,$A11,'Casos de prueba'!$L:$L,"Bloqueado") -> 0 | F11: =COUNTIFS('Casos de prueba'!$B:$B,$A11,'Casos de prueba'!$L:$L,"Pendiente") -> 6 | G11: =IF(B11=0,0,C11/B11) -> 0
A12: Categorías y sitios | B12: =COUNTIF('Casos de prueba'!$B:$B,A12) -> 7 | C12: =COUNTIFS('Casos de prueba'!$B:$B,$A12,'Casos de prueba'!$L:$L,"Aprobado") -> 0 | D12: =COUNTIFS('Casos de prueba'!$B:$B,$A12,'Casos de prueba'!$L:$L,"Fallido") -> 0 | E12: =COUNTIFS('Casos de prueba'!$B:$B,$A12,'Casos de prueba'!$L:$L,"Bloqueado") -> 0 | F12: =COUNTIFS('Casos de prueba'!$B:$B,$A12,'Casos de prueba'!$L:$L,"Pendiente") -> 7 | G12: =IF(B12=0,0,C12/B12) -> 0
A13: Secciones y sillas | B13: =COUNTIF('Casos de prueba'!$B:$B,A13) -> 9 | C13: =COUNTIFS('Casos de prueba'!$B:$B,$A13,'Casos de prueba'!$L:$L,"Aprobado") -> 0 | D13: =COUNTIFS('Casos de prueba'!$B:$B,$A13,'Casos de prueba'!$L:$L,"Fallido") -> 0 | E13: =COUNTIFS('Casos de prueba'!$B:$B,$A13,'Casos de prueba'!$L:$L,"Bloqueado") -> 0 | F13: =COUNTIFS('Casos de prueba'!$B:$B,$A13,'Casos de prueba'!$L:$L,"Pendiente") -> 9 | G13: =IF(B13=0,0,C13/B13) -> 0
A14: Órdenes y tickets | B14: =COUNTIF('Casos de prueba'!$B:$B,A14) -> 12 | C14: =COUNTIFS('Casos de prueba'!$B:$B,$A14,'Casos de prueba'!$L:$L,"Aprobado") -> 0 | D14: =COUNTIFS('Casos de prueba'!$B:$B,$A14,'Casos de prueba'!$L:$L,"Fallido") -> 0 | E14: =COUNTIFS('Casos de prueba'!$B:$B,$A14,'Casos de prueba'!$L:$L,"Bloqueado") -> 0 | F14: =COUNTIFS('Casos de prueba'!$B:$B,$A14,'Casos de prueba'!$L:$L,"Pendiente") -> 12 | G14: =IF(B14=0,0,C14/B14) -> 0
A15: Pagos | B15: =COUNTIF('Casos de prueba'!$B:$B,A15) -> 16 | C15: =COUNTIFS('Casos de prueba'!$B:$B,$A15,'Casos de prueba'!$L:$L,"Aprobado") -> 0 | D15: =COUNTIFS('Casos de prueba'!$B:$B,$A15,'Casos de prueba'!$L:$L,"Fallido") -> 0 | E15: =COUNTIFS('Casos de prueba'!$B:$B,$A15,'Casos de prueba'!$L:$L,"Bloqueado") -> 0 | F15: =COUNTIFS('Casos de prueba'!$B:$B,$A15,'Casos de prueba'!$L:$L,"Pendiente") -> 16 | G15: =IF(B15=0,0,C15/B15) -> 0
A16: Wallet | B16: =COUNTIF('Casos de prueba'!$B:$B,A16) -> 5 | C16: =COUNTIFS('Casos de prueba'!$B:$B,$A16,'Casos de prueba'!$L:$L,"Aprobado") -> 0 | D16: =COUNTIFS('Casos de prueba'!$B:$B,$A16,'Casos de prueba'!$L:$L,"Fallido") -> 0 | E16: =COUNTIFS('Casos de prueba'!$B:$B,$A16,'Casos de prueba'!$L:$L,"Bloqueado") -> 0 | F16: =COUNTIFS('Casos de prueba'!$B:$B,$A16,'Casos de prueba'!$L:$L,"Pendiente") -> 5 | G16: =IF(B16=0,0,C16/B16) -> 0
... A19: Seguridad y almacenamiento | B19: =COUNTIF('Casos de prueba'!$B:$B,A19) -> 6 | C19: =COUNTIFS('Casos de prueba'!$B:$B,$A19,'Casos de prueba'!$L:$L,"Aprobado") -> 0 | D19: =COUNTIFS('Casos de prueba'!$B:$B,$A19,'Casos de prueba'!$L:$L,"Fallido") -> 0 | E19: =COUNTIFS('Casos de prueba'!$B:$B,$A19,'Casos de prueba'!$L:$L,"Bloqueado") -> 0 | F19: =COUNTIFS('Casos de prueba'!$B:$B,$A19,'Casos de prueba'!$L:$L,"Pendiente") -> 6 | G19: =IF(B19=0,0,C19/B19) -> 0
A20: TOTAL | B20: =SUM(B5:B19) -> 151 | C20: =SUM(C5:C19) -> 0 | D20: =SUM(D5:D19) -> 0 | E20: =SUM(E5:E19) -> 0 | F20: =SUM(F5:F19) -> 151 | G20: =IF(B20=0,0,C20/B20) -> 0
A22: Por tipo de prueba
A23: Tipo | B23: Total
A24: Positivo | B24: =COUNTIF('Casos de prueba'!$D:$D,A24) -> 42
A25: Negativo | B25: =COUNTIF('Casos de prueba'!$D:$D,A25) -> 66
A26: Límite | B26: =COUNTIF('Casos de prueba'!$D:$D,A26) -> 11
A27: Seguridad | B27: =COUNTIF('Casos de prueba'!$D:$D,A27) -> 22
A28: Concurrencia | B28: =COUNTIF('Casos de prueba'!$D:$D,A28) -> 2
A29: Integración | B29: =COUNTIF('Casos de prueba'!$D:$D,A29) -> 8
A32: Casos que verifican huecos conocidos (se espera que fallen hoy)
A33: Ver la columna Observaciones con el texto «Hueco conocido» en la hoja de casos.

Sheet Casos de prueba
A1: ID | B1: Módulo | C1: Requisito / referencia | D1: Tipo | E1: Prioridad | F1: Descripción | G1: Precondiciones | H1: Pasos | I1: Datos de entrada | J1: Resultado esperado | K1: Resultado obtenido | L1: Estado | M1: Fecha | N1: Responsable | O1: Observaciones
A2: CP-AUT-01 | B2: Autenticación | C2: 3.1 /register | D2: Positivo | E2: Alta | F2: Registro exitoso con Gmail y datos válidos | G2: Correo no registrado | H2: 1. POST /api/v1/auth/register 2. Revisar el correo de activación | I2: email: nuevo.usuario@gmail.com password: Clave#2026 fullName: Cristofer Lozano | J2: 201. Cuenta creada pendiente de activación y correo con código enviado | L2: Pendiente
A3: CP-AUT-02 | B3: Autenticación | C3: 3.1 /register | D3: Negativo | E3: Alta | F3: Registro con correo que no es Gmail | G3: Ninguna | H3: 1. POST /register con correo de otro dominio | I3: email: ana@hotmail.com | J3: 400 INVALID_EMAIL | L3: Pendiente
A4: CP-AUT-03 | B4: Autenticación | C4: 4 Cuenta | D4: Negativo | E4: Alta | F4: Registro con contraseña que incumple la política | G4: Ninguna | H4: 1. POST /register con clave sin mayúscula, dígito ni especial | I4: password: clave1234 | J4: 400 INVALID_PASSWORD | L4: Pendiente
A5: CP-AUT-04 | B5: Autenticación | C5: 4 Cuenta | D5: Negativo | E5: Media | F5: Registro con nombre de una sola palabra o con números | G5: Ninguna | H5: 1. POST /register con fullName inválido | I5: fullName: Juan / Ju4n P3r3z | J5: 400 INVALID_NAME | L5: Pendiente
A6: CP-AUT-05 | B6: Autenticación | C6: 4 Cuenta | D6: Límite | E6: Media | F6: Nombre de 31 caracteres (límite máximo 30) | G6: Ninguna | H6: 1. POST /register con nombre de 31 caracteres | I6: fullName: 31 caracteres alfabéticos en dos palabras | J6: 400 INVALID_NAME. Con 30 caracteres exactos debe aceptarse | L6: Pendiente
A7: CP-AUT-06 | B7: Autenticación | C7: 3.1 /register | D7: Negativo | E7: Alta | F7: Registro con correo ya existente | G7: Usuario ya registrado | H7: 1. POST /register con el mismo correo | I7: email existente | J7: 400 EMAIL_ALREADY_EXISTS | L7: Pendiente
A8: CP-AUT-07 | B8: Autenticación | C8: 3.1 /activate | D8: Positivo | E8: Alta | F8: Activación de cuenta con código válido | G8: Usuario registrado sin activar | H8: 1. POST /activate con el código del correo 2. Iniciar sesión | I8: email + activationCode válido | J8: 200. La cuenta queda activa y el login funciona | L8: Pendiente
A9: CP-AUT-08 | B9: Autenticación | C9: 3.1 /activate | D9: Negativo | E9: Alta | F9: Activación con código incorrecto | G9: Usuario registrado sin activar | H9: 1. POST /activate con código errado | I9: activationCode: 000000 | J9: 400 INVALID_ACTIVATION_CODE | L9: Pendiente
A10: CP-AUT-09 | B10: Autenticación | C10: 3.1 /activate | D10: Negativo | E10: Media | F10: Activación con código vencido | G10: Código generado y vencido | H10: 1. Esperar el vencimiento 2. POST /activate | I10: código vencido | J10: 400 ACTIVATION_CODE_EXPIRED | L10: Pendiente
A11: CP-AUT-10 | B11: Autenticación | C11: 3.1 /activate | D11: Negativo | E11: Baja | F11: Activar una cuenta que ya está activa | G11: Cuenta activa | H11: 1. POST /activate | I11: email de cuenta activa | J11: 400 ACCOUNT_ALREADY_ACTIVATED | L11: Pendiente
A12: CP-AUT-11 | B12: Autenticación | C12: 3.1 /resend-activation | D12: Negativo | E12: Baja | F12: Reenviar activación a cuenta ya activada | G12: Cuenta activa | H12: 1. POST /resend-activation | I12: email de cuenta activa | J12: 400 EMAIL_ALREADY_ACTIVATED | L12: Pendiente
A13: CP-AUT-12 | B13: Autenticación | C13: 3.1 /login | D13: Positivo | E13: Alta | F13: Login exitoso | G13: Cuenta activa | H13: 1. POST /login con credenciales válidas | I13: email + password correctos | J13: 200 con accessToken, refreshToken, userId, alias y role | L13: Pendiente
... A16: CP-AUT-15 | B16: Autenticación | C16: 3.1 /login | D16: Negativo | E16: Alta | F16: Login con contraseña incorrecta | G16: Cuenta activa | H16: 1. POST /login con clave errada | I16: password incorrecto | J16: 400 INVALID_CREDENTIALS | L16: Pendiente
A17: CP-AUT-16 | B17: Autenticación | C17: 4 Cuenta | D17: Límite | E17: Alta | F17: Bloqueo tras 5 intentos fallidos en 15 minutos | G17: Cuenta activa | H17: 1. Hacer 5 logins fallidos seguidos 2. Intentar un sexto login con clave correcta 3. Esperar el tiempo de bloqueo 4. Reintentar | I17: clave incorrecta x5 | J17: 400 ACCOUNT_LOCKED en el sexto intento. Se desbloquea al vencer el plazo | L17: Pendiente | O17: El bloqueo hoy dura 1 minuto (TODO volver a 30)
A18: CP-AUT-17 | B18: Autenticación | C18: 3.1 /login | D18: Negativo | E18: Media | F18: Login con cuenta bloqueada, desactivada o eliminada | G18: Cuentas en cada estado | H18: 1. POST /login con cada cuenta | I18: credenciales correctas | J18: 400 ACCOUNT_BLOCKED / ACCOUNT_DEACTIVATED / ACCOUNT_DELETED según el caso | L18: Pendiente
A19: CP-AUT-18 | B19: Autenticación | C19: 3.1 /refresh | D19: Positivo | E19: Alta | F19: Renovar tokens con refresh token válido | G19: Sesión iniciada | H19: 1. POST /refresh con el refreshToken | I19: refreshToken vigente | J19: 200 con nuevos tokens | L19: Pendiente
A20: CP-AUT-19 | B20: Autenticación | C20: 3.1 /refresh | D20: Negativo | E20: Alta | F20: Refresh con token revocado tras logout | G20: Logout realizado | H20: 1. POST /logout 2. POST /refresh con el token anterior | I20: refreshToken revocado | J20: 400 REFRESH_TOKEN_REVOKED | L20: Pendiente
A21: CP-AUT-20 | B21: Autenticación | C21: 3.1 /refresh | D21: Negativo | E21: Media | F21: Refresh con token vencido | G21: Refresh token con más de 7 días | H21: 1. POST /refresh | I21: refreshToken vencido | J21: 400 REFRESH_TOKEN_EXPIRED | L21: Pendiente
A22: CP-AUT-21 | B22: Autenticación | C22: 6 Registro/login | D22: Integración | E22: Media | F22: Logout sincronizado entre pestañas (web) | G22: Dos pestañas con sesión | H22: 1. Cerrar sesión en la pestaña A 2. Observar la pestaña B | I22: — | J22: La pestaña B redirige a /login | L22: Pendiente
A23: CP-AUT-22 | B23: Autenticación | C23: 6 Registro/login | D23: Integración | E23: Alta | F23: JWT de acceso vencido provoca refresh automático (web) | G23: Sesión con access token de 15 min vencido | H23: 1. Esperar 15 min 2. Ejecutar una acción protegida | I23: — | J23: El cliente recibe 401, renueva con refresh y repite la acción sin cerrar sesión. Si el refresh falla, hace logout | L23: Pendiente
A24: CP-AUT-23 | B24: Autenticación | C24: 3.1 /recover-password | D24: Seguridad | E24: Alta | F24: Recuperación de contraseña no revela si el correo existe | G24: Un correo registrado y otro no | H24: 1. POST /recover-password con cada correo | I24: email existente / inexistente | J24: 200 con el mismo mensaje genérico en ambos casos | L24: Pendiente
A25: CP-AUT-24 | B25: Autenticación | C25: 3.1 /reset-password | D25: Positivo | E25: Alta | F25: Restablecer contraseña con código válido | G25: Código de recuperación recibido | H25: 1. POST /reset-password 2. Login con la nueva clave | I25: código + clave nueva y confirmación | J25: 200 y login exitoso con la nueva clave | L25: Pendiente
A26: CP-AUT-25 | B26: Autenticación | C26: 3.1 /reset-password | D26: Negativo | E26: Media | F26: Restablecer con código ya usado o vencido | G26: Código usado / vencido | H26: 1. POST /reset-password | I26: código reutilizado o vencido | J26: 400 RECOVERY_CODE_USED / RECOVERY_CODE_EXPIRED | L26: Pendiente
A27: CP-AUT-26 | B27: Autenticación | C27: 3.1 /reset-password | D27: Negativo | E27: Media | F27: Restablecer con contraseñas que no coinciden | G27: Código válido | H27: 1. POST /reset-password | I27: nueva ≠ confirmación | J27: 400 PASSWORD_MISMATCH | L27: Pendiente
A28: CP-AUT-27 | B28: Autenticación | C28: 3.1 /oauth | D28: Positivo | E28: Media | F28: Login con Google por OAuth2 (web) | G28: Credenciales de Google configuradas | H28: 1. Pulsar «Continuar con Google» en /login 2. Autorizar | I28: cuenta Google válida | J28: 302 a /login?oauth=true&token=... y sesión iniciada | L28: Pendiente
A29: CP-AUT-28 | B29: Autenticación | C29: 8 Bordes | D29: Seguridad | E29: Alta | F29: Open redirect: frontend_redirect_uri fuera de la lista permitida | G29: Ninguna | H29: 1. GET /oauth/google con frontend_redirect_uri externo | I29: frontend_redirect_uri: https://sitio-malicioso.com | J29: La petición se rechaza. Nunca redirige al dominio externo | L29: Pendiente
... A109: CP-ORD-06 | B109: Órdenes y tickets | C109: 4 Órdenes | D109: Negativo | E109: Alta | F109: Cancelar una orden ya pagada | G109: Orden PAID | H109: 1. POST /orders/{id}/cancel | I109: — | J109: 409 | L109: Pendiente
A110: CP-ORD-07 | B110: Órdenes y tickets | C110: 8 Huecos | D110: Seguridad | E110: Alta | F110: Cancelar la orden de otro usuario | G110: Orden del usuario A. Sesión del usuario B | H110: 1. Usuario B hace POST /orders/{id de A}/cancel | I110: — | J110: Debería rechazarse (403) | L110: Pendiente | O110: Hueco conocido: hoy no se comprueba el dueño. Si se ejecuta la cancelación, registrar defecto
A111: CP-ORD-08 | B111: Órdenes y tickets | C111: 8 Huecos | D111: Seguridad | E111: Alta | F111: Consultar tickets de otro usuario por userId | G111: Dos usuarios con tickets | H111: 1. Usuario B hace GET /tickets/user/{id de A} | I111: — | J111: Debería rechazarse (403) | L111: Pendiente | O111: Hueco conocido: no se verifica que sea el mismo usuario
A112: CP-ORD-09 | B112: Órdenes y tickets | C112: 3.10 checkin | D112: Positivo | E112: Alta | F112: Check-in de un ticket pagado | G112: Ticket PAID, no expirado | H112: 1. POST /tickets/{id}/checkin | I112: validatedBy: nombre del validador | J112: 200. Ticket USED y registro en ticket_checkin | L112: Pendiente
A113: CP-ORD-10 | B113: Órdenes y tickets | C113: 3.10 checkin | D113: Negativo | E113: Alta | F113: Check-in repetido del mismo ticket | G113: Ticket USED | H113: 1. POST /tickets/{id}/checkin otra vez | I113: — | J113: 400 por ticket ya usado | L113: Pendiente
A114: CP-ORD-11 | B114: Órdenes y tickets | C114: 3.10 checkin | D114: Negativo | E114: Alta | F114: Check-in de ticket no pagado o expirado | G114: Ticket PENDING / expirado | H114: 1. POST /tickets/{id}/checkin | I114: — | J114: 400 | L114: Pendiente
A115: CP-ORD-12 | B115: Órdenes y tickets | C115: 8 Huecos | D115: Seguridad | E115: Alta | F115: Check-in realizado por un usuario sin rol de organizador | G115: Ticket PAID. Sesión USER | H115: 1. POST /tickets/{id}/checkin con token de USER | I115: — | J115: Debería denegarse | L115: Pendiente | O115: Hueco conocido: no hay @PreAuthorize ni rol staff. Probar solo por API (no hay escáner QR)
A116: CP-PAG-01 | B116: Pagos | C116: 3.11 /payments | D116: Positivo | E116: Alta | F116: Crear pago por QR sin wallet | G116: Orden DRAFT | H116: 1. POST /payments con orderId y paymentMethod QR | I116: applyWalletCredit: false | J116: 201 (sin sobre ApiResponse). Pago PENDING y orden PAYMENT_PENDING | L116: Pendiente
A117: CP-PAG-02 | B117: Pagos | C117: 3.11 webhook | D117: Integración | E117: Alta | F117: Webhook de pago aprobado | G117: Pago PENDING en pasarela fake | H117: 1. Aprobar el pago en la pasarela fake (puerto 4001) 2. Verificar orden, tickets y sillas | I117: firma HMAC válida | J117: Pago APPROVED, orden PAID, tickets PAID y sillas SOLD | L117: Pendiente
A118: CP-PAG-03 | B118: Pagos | C118: 3.11 webhook | D118: Integración | E118: Alta | F118: Webhook de pago rechazado | G118: Pago PENDING | H118: 1. Rechazar el pago en la pasarela fake 2. Verificar estados | I118: firma HMAC válida | J118: Pago REJECTED. Sillas AVAILABLE, tickets y orden cancelados | L118: Pendiente
A119: CP-PAG-04 | B119: Pagos | C119: 3.11 webhook | D119: Seguridad | E119: Alta | F119: Webhook con firma HMAC inválida | G119: Ninguna | H119: 1. POST /webhooks/payment con X-Signature alterada | I119: firma incorrecta | J119: 401 y ningún cambio de estado | L119: Pendiente
A120: CP-PAG-05 | B120: Pagos | C120: 8 Bordes | D120: Concurrencia | E120: Alta | F120: Webhook duplicado (mismo gateway_event_id) | G120: Webhook ya procesado | H120: 1. Reenviar el mismo webhook | I120: mismo eventId | J120: 200 sin efecto doble (idempotente) | L120: Pendiente
A121: CP-PAG-06 | B121: Pagos | C121: 4 Estados | D121: Negativo | E121: Media | F121: Pago de una orden que ya no está en DRAFT | G121: Orden PAID o CANCELLED | H121: 1. POST /payments | I121: orderId de orden cerrada | J121: 409 por transición inválida | L121: Pendiente
...
